[2022-09-10T17:58:28.918+0000] {taskinstance.py:1171} INFO - Dependencies all met for <TaskInstance: spotify_etl.spotify_etl scheduled__2022-09-09T00:00:00+00:00 [queued]>
[2022-09-10T17:58:28.924+0000] {taskinstance.py:1171} INFO - Dependencies all met for <TaskInstance: spotify_etl.spotify_etl scheduled__2022-09-09T00:00:00+00:00 [queued]>
[2022-09-10T17:58:28.925+0000] {taskinstance.py:1368} INFO - 
--------------------------------------------------------------------------------
[2022-09-10T17:58:28.926+0000] {taskinstance.py:1369} INFO - Starting attempt 2 of 2
[2022-09-10T17:58:28.927+0000] {taskinstance.py:1370} INFO - 
--------------------------------------------------------------------------------
[2022-09-10T17:58:28.935+0000] {taskinstance.py:1389} INFO - Executing <Task(PythonOperator): spotify_etl> on 2022-09-09 00:00:00+00:00
[2022-09-10T17:58:28.943+0000] {standard_task_runner.py:52} INFO - Started process 365 to run task
[2022-09-10T17:58:28.946+0000] {standard_task_runner.py:79} INFO - Running: ['***', 'tasks', 'run', 'spotify_etl', 'spotify_etl', 'scheduled__2022-09-09T00:00:00+00:00', '--job-id', '17', '--raw', '--subdir', 'DAGS_FOLDER/spotify_dag.py', '--cfg-path', '/tmp/tmp4py3m8ws', '--error-file', '/tmp/tmpy3lrmikk']
[2022-09-10T17:58:28.948+0000] {standard_task_runner.py:80} INFO - Job 17: Subtask spotify_etl
[2022-09-10T17:58:28.988+0000] {task_command.py:371} INFO - Running <TaskInstance: spotify_etl.spotify_etl scheduled__2022-09-09T00:00:00+00:00 [running]> on host aafa6629e766
[2022-09-10T17:58:29.054+0000] {taskinstance.py:1583} INFO - Exporting the following env vars:
AIRFLOW_CTX_DAG_EMAIL=c.mendozar@outlook.com
AIRFLOW_CTX_DAG_OWNER=***
AIRFLOW_CTX_DAG_ID=spotify_etl
AIRFLOW_CTX_TASK_ID=spotify_etl
AIRFLOW_CTX_EXECUTION_DATE=2022-09-09T00:00:00+00:00
AIRFLOW_CTX_TRY_NUMBER=2
AIRFLOW_CTX_DAG_RUN_ID=scheduled__2022-09-09T00:00:00+00:00
[2022-09-10T17:58:29.058+0000] {oauth2.py:471} INFO - User authentication requires interaction with your web browser. Once you enter your credentials and give authorization, you will be redirected to a url.  Paste that url you were directed to to complete the authorization.
[2022-09-10T17:58:29.060+0000] {taskinstance.py:1902} ERROR - Task failed with exception
Traceback (most recent call last):
  File "/home/airflow/.local/lib/python3.7/site-packages/airflow/operators/python.py", line 171, in execute
    return_value = self.execute_callable()
  File "/home/airflow/.local/lib/python3.7/site-packages/airflow/operators/python.py", line 189, in execute_callable
    return self.python_callable(*self.op_args, **self.op_kwargs)
  File "/opt/airflow/dags/spotify/etl.py", line 41, in song_etl
    redirect_uri = redirect_uri
  File "/home/airflow/.local/lib/python3.7/site-packages/spotipy/util.py", line 99, in prompt_for_user_token
    code = sp_oauth.get_auth_response()
  File "/home/airflow/.local/lib/python3.7/site-packages/spotipy/oauth2.py", line 490, in get_auth_response
    return self._get_auth_response_local_server(redirect_port)
  File "/home/airflow/.local/lib/python3.7/site-packages/spotipy/oauth2.py", line 457, in _get_auth_response_local_server
    server = start_local_http_server(redirect_port)
  File "/home/airflow/.local/lib/python3.7/site-packages/spotipy/oauth2.py", line 1303, in start_local_http_server
    server = HTTPServer(("127.0.0.1", port), handler)
  File "/usr/local/lib/python3.7/socketserver.py", line 452, in __init__
    self.server_bind()
  File "/usr/local/lib/python3.7/http/server.py", line 137, in server_bind
    socketserver.TCPServer.server_bind(self)
  File "/usr/local/lib/python3.7/socketserver.py", line 466, in server_bind
    self.socket.bind(self.server_address)
OSError: [Errno 98] Address already in use
[2022-09-10T17:58:29.071+0000] {taskinstance.py:1412} INFO - Marking task as FAILED. dag_id=spotify_etl, task_id=spotify_etl, execution_date=20220909T000000, start_date=20220910T175828, end_date=20220910T175829
[2022-09-10T17:58:29.084+0000] {warnings.py:110} WARNING - /home/***/.local/lib/python3.7/site-packages/***/utils/email.py:119: PendingDeprecationWarning: Fetching SMTP credentials from configuration variables will be deprecated in a future release. Please set credentials using a connection instead.
  send_mime_email(e_from=mail_from, e_to=recipients, mime_msg=msg, conn_id=conn_id, dryrun=dryrun)

[2022-09-10T17:58:29.087+0000] {configuration.py:562} WARNING - section/key [smtp/smtp_user] not found in config
[2022-09-10T17:58:29.088+0000] {email.py:228} INFO - Email alerting: attempt 1
[2022-09-10T17:58:29.095+0000] {configuration.py:562} WARNING - section/key [smtp/smtp_user] not found in config
[2022-09-10T17:58:29.097+0000] {email.py:228} INFO - Email alerting: attempt 1
[2022-09-10T17:58:29.099+0000] {taskinstance.py:1957} ERROR - Failed to send email to: ['c.mendozar@outlook.com']
Traceback (most recent call last):
  File "/home/airflow/.local/lib/python3.7/site-packages/airflow/models/taskinstance.py", line 1463, in _run_raw_task
    self._execute_task_with_callbacks(context, test_mode)
  File "/home/airflow/.local/lib/python3.7/site-packages/airflow/models/taskinstance.py", line 1610, in _execute_task_with_callbacks
    result = self._execute_task(context, task_orig)
  File "/home/airflow/.local/lib/python3.7/site-packages/airflow/models/taskinstance.py", line 1671, in _execute_task
    result = execute_callable(context=context)
  File "/home/airflow/.local/lib/python3.7/site-packages/airflow/operators/python.py", line 171, in execute
    return_value = self.execute_callable()
  File "/home/airflow/.local/lib/python3.7/site-packages/airflow/operators/python.py", line 189, in execute_callable
    return self.python_callable(*self.op_args, **self.op_kwargs)
  File "/opt/airflow/dags/spotify/etl.py", line 41, in song_etl
    redirect_uri = redirect_uri
  File "/home/airflow/.local/lib/python3.7/site-packages/spotipy/util.py", line 99, in prompt_for_user_token
    code = sp_oauth.get_auth_response()
  File "/home/airflow/.local/lib/python3.7/site-packages/spotipy/oauth2.py", line 490, in get_auth_response
    return self._get_auth_response_local_server(redirect_port)
  File "/home/airflow/.local/lib/python3.7/site-packages/spotipy/oauth2.py", line 457, in _get_auth_response_local_server
    server = start_local_http_server(redirect_port)
  File "/home/airflow/.local/lib/python3.7/site-packages/spotipy/oauth2.py", line 1303, in start_local_http_server
    server = HTTPServer(("127.0.0.1", port), handler)
  File "/usr/local/lib/python3.7/socketserver.py", line 452, in __init__
    self.server_bind()
  File "/usr/local/lib/python3.7/http/server.py", line 137, in server_bind
    socketserver.TCPServer.server_bind(self)
  File "/usr/local/lib/python3.7/socketserver.py", line 466, in server_bind
    self.socket.bind(self.server_address)
OSError: [Errno 98] Address already in use

During handling of the above exception, another exception occurred:

Traceback (most recent call last):
  File "/home/airflow/.local/lib/python3.7/site-packages/airflow/models/taskinstance.py", line 2339, in email_alert
    send_email(task.email, subject, html_content)
  File "/home/airflow/.local/lib/python3.7/site-packages/airflow/utils/email.py", line 71, in send_email
    **kwargs,
  File "/home/airflow/.local/lib/python3.7/site-packages/airflow/utils/email.py", line 119, in send_email_smtp
    send_mime_email(e_from=mail_from, e_to=recipients, mime_msg=msg, conn_id=conn_id, dryrun=dryrun)
  File "/home/airflow/.local/lib/python3.7/site-packages/airflow/utils/email.py", line 230, in send_mime_email
    smtp_conn = _get_smtp_connection(smtp_host, smtp_port, smtp_timeout, smtp_ssl)
  File "/home/airflow/.local/lib/python3.7/site-packages/airflow/utils/email.py", line 264, in _get_smtp_connection
    else smtplib.SMTP(host=host, port=port, timeout=timeout)
  File "/usr/local/lib/python3.7/smtplib.py", line 251, in __init__
    (code, msg) = self.connect(host, port)
  File "/usr/local/lib/python3.7/smtplib.py", line 336, in connect
    self.sock = self._get_socket(host, port, self.timeout)
  File "/usr/local/lib/python3.7/smtplib.py", line 307, in _get_socket
    self.source_address)
  File "/usr/local/lib/python3.7/socket.py", line 728, in create_connection
    raise err
  File "/usr/local/lib/python3.7/socket.py", line 716, in create_connection
    sock.connect(sa)
OSError: [Errno 99] Cannot assign requested address

During handling of the above exception, another exception occurred:

Traceback (most recent call last):
  File "/home/airflow/.local/lib/python3.7/site-packages/airflow/models/taskinstance.py", line 1955, in handle_failure
    self.email_alert(error, task)
  File "/home/airflow/.local/lib/python3.7/site-packages/airflow/models/taskinstance.py", line 2341, in email_alert
    send_email(task.email, subject, html_content_err)
  File "/home/airflow/.local/lib/python3.7/site-packages/airflow/utils/email.py", line 71, in send_email
    **kwargs,
  File "/home/airflow/.local/lib/python3.7/site-packages/airflow/utils/email.py", line 119, in send_email_smtp
    send_mime_email(e_from=mail_from, e_to=recipients, mime_msg=msg, conn_id=conn_id, dryrun=dryrun)
  File "/home/airflow/.local/lib/python3.7/site-packages/airflow/utils/email.py", line 230, in send_mime_email
    smtp_conn = _get_smtp_connection(smtp_host, smtp_port, smtp_timeout, smtp_ssl)
  File "/home/airflow/.local/lib/python3.7/site-packages/airflow/utils/email.py", line 264, in _get_smtp_connection
    else smtplib.SMTP(host=host, port=port, timeout=timeout)
  File "/usr/local/lib/python3.7/smtplib.py", line 251, in __init__
    (code, msg) = self.connect(host, port)
  File "/usr/local/lib/python3.7/smtplib.py", line 336, in connect
    self.sock = self._get_socket(host, port, self.timeout)
  File "/usr/local/lib/python3.7/smtplib.py", line 307, in _get_socket
    self.source_address)
  File "/usr/local/lib/python3.7/socket.py", line 728, in create_connection
    raise err
  File "/usr/local/lib/python3.7/socket.py", line 716, in create_connection
    sock.connect(sa)
OSError: [Errno 99] Cannot assign requested address
[2022-09-10T17:58:29.111+0000] {standard_task_runner.py:97} ERROR - Failed to execute job 17 for task spotify_etl ([Errno 98] Address already in use; 365)
[2022-09-10T17:58:29.165+0000] {local_task_job.py:156} INFO - Task exited with return code 1
[2022-09-10T17:58:29.187+0000] {local_task_job.py:279} INFO - 0 downstream tasks scheduled from follow-on schedule check
